const catchAsync = require("./../utils/catchAsync");
const AppError = require("./../utils/apiError");

exports.deleteOne = (Model) =>
  catchAsync(async (req, res, next) => {
    const doc = await Model.findByIdAndDelete(req.params.id);

    if (!doc) {
      return next(new AppError("No document found with that ID", 404));
    }

    res.status(200).json({
      status: "success",
      data: {
        doc,
      },
    });
  });

exports.create = (Model) =>
  catchAsync(async (req, res, next) => {
    const newDoc = await Model.create(req.body);
    res.status(201).json({
      status: "success",
      data: newDoc,
    });
  });

exports.getOne = (Model, populateOptions) =>
  catchAsync(async (req, res, next) => {
    let query = Model.findById(req.params.id);

    if (populateOptions) {
      query = query.populate(populateOptions);
    }

    const doc = await query;

    if (!doc) {
      return next(new AppError("No document found with that ID", 404));
    }

    res.status(200).json({
      status: "success",
      data: doc,
    });
  });


exports.getAll = (Model) =>
  catchAsync(async (req, res, next) => {
    const docs = await Model.find()

    if(!docs) {
      return next(new AppError("Something went wrong", 500))
    }

    res.status(200).json({
      status: "success",
      docs
    })
  }) 